Workbook

Sheet Read Me
A1: Care Access Navigator: Rubric Traceability Matrix
A2: Every rubric line item from all 7 courses + the capstone design doc, split into single checkable requirements.
A4: How it was verified (2026-10-13)
A5: 1. Text of every course PDF/DOCX in dae_6mon_coh2_AC, Downloads, Desktop and Documents was searched for each requirement.
A6: 2. Live-system facts come from system-generated evidence collected 10/13 (Keycloak kcadm, Microsoft Graph, Azure Monitor).
A7: 3. GitHub = your local git clone, which matches origin/main as of 10/12 (direct GitHub API access was not available).
A8: 4. Risk Management rows are keyword-verified (each required term is present in the PDF), not re-graded line by line.
A10: Status definitions
A11: Met | B11: Evidence exists and matches the rubric wording.
A12: Met (equivalent lab) | B12: Done, but in an equivalent environment rather than the exact tool the rubric names.
A13: Partial | B13: Some of it exists (designed, drafted, or only part of the requirement).
A14: Gap | B14: Nothing found. Must be built.
A15: Risk: tool substitution | B15: Rubric names a specific tool you did not use. Needs instructor acceptance or rebuild.
A16: Not found on computer | B16: Probably submitted elsewhere (e.g., Schoology) but not on this computer. Confirm the grade.
A18: Cells you edit
A19: Yellow columns on the Requirements sheet | B19: My status · Date closed · New evidence file. Pick "Done" when you finish; the Summary updates itself.
A20: Example | B20: CS-14 · My status = Done · Date closed = 2026-10-15 · New evidence = cloud_security_1/c4-saml/EVID-Week5-Day4-001.png

Sheet Summary
A1: Summary by course (live: counts update from the Requirements sheet)
A3: Course | B3: Requirements | C3: Met | D3: Met (equivalent lab) | E3: Partial | F3: Gap | G3: Risk: tool substitution | H3: Not found on computer | I3: Open (Partial+Gap+Risk+NF) | J3: Closed by you | K3: Still open after your updates | L3: % verified Met
A4: Cybersecurity Basics 1 | B4: =COUNTIF(Requirements!$B$2:$B$185,A4) -> 11 | C4: =COUNTIFS(Requirements!$B$2:$B$185,$A4,Requirements!$E$2:$E$185,C$3) -> 3 | D4: =COUNTIFS(Requirements!$B$2:$B$185,$A4,Requirements!$E$2:$E$185,D$3) -> 0 | E4: =COUNTIFS(Requirements!$B$2:$B$185,$A4,Requirements!$E$2:$E$185,E$3) -> 1 | F4: =COUNTIFS(Requirements!$B$2:$B$185,$A4,Requirements!$E$2:$E$185,F$3) -> 0 | G4: =COUNTIFS(Requirements!$B$2:$B$185,$A4,Requirements!$E$2:$E$185,G$3) -> 0 | H4: =COUNTIFS(Requirements!$B$2:$B$185,$A4,Requirements!$E$2:$E$185,H$3) -> 7 | I4: =SUM(E4:H4) -> 8 | J4: =COUNTIFS(Requirements!$B$2:$B$185,$A4,Requirements!$E$2:$E$185,"<>Met",Requirements!$K$2:$K$185,"Done")+COUNTIFS(Requirements!$B$2:$B$185,$A4,Requirements!$E$2:$E$185,"<>Met",Requirements!$K$2:$K$185,"Instructor accepted") -> 0 | K4: =MAX(0,I4-J4) -> 8 | L4: =IF(B4=0,0,(C4+D4)/B4) -> 0.27272727
A5: Cyber Threats & Vulnerabilities 1 | B5: =COUNTIF(Requirements!$B$2:$B$185,A5) -> 16 | C5: =COUNTIFS(Requirements!$B$2:$B$185,$A5,Requirements!$E$2:$E$185,C$3) -> 5 | D5: =COUNTIFS(Requirements!$B$2:$B$185,$A5,Requirements!$E$2:$E$185,D$3) -> 0 | E5: =COUNTIFS(Requirements!$B$2:$B$185,$A5,Requirements!$E$2:$E$185,E$3) -> 5 | F5: =COUNTIFS(Requirements!$B$2:$B$185,$A5,Requirements!$E$2:$E$185,F$3) -> 0 | G5: =COUNTIFS(Requirements!$B$2:$B$185,$A5,Requirements!$E$2:$E$185,G$3) -> 0 | H5: =COUNTIFS(Requirements!$B$2:$B$185,$A5,Requirements!$E$2:$E$185,H$3) -> 6 | I5: =SUM(E5:H5) -> 11 | J5: =COUNTIFS(Requirements!$B$2:$B$185,$A5,Requirements!$E$2:$E$185,"<>Met",Requirements!$K$2:$K$185,"Done")+COUNTIFS(Requirements!$B$2:$B$185,$A5,Requirements!$E$2:$E$185,"<>Met",Requirements!$K$2:$K$185,"Instructor accepted") -> 0 | K5: =MAX(0,I5-J5) -> 11 | L5: =IF(B5=0,0,(C5+D5)/B5) -> 0.3125
A6: Network Security 1 | B6: =COUNTIF(Requirements!$B$2:$B$185,A6) -> 18 | C6: =COUNTIFS(Requirements!$B$2:$B$185,$A6,Requirements!$E$2:$E$185,C$3) -> 11 | D6: =COUNTIFS(Requirements!$B$2:$B$185,$A6,Requirements!$E$2:$E$185,D$3) -> 0 | E6: =COUNTIFS(Requirements!$B$2:$B$185,$A6,Requirements!$E$2:$E$185,E$3) -> 5 | F6: =COUNTIFS(Requirements!$B$2:$B$185,$A6,Requirements!$E$2:$E$185,F$3) -> 2 | G6: =COUNTIFS(Requirements!$B$2:$B$185,$A6,Requirements!$E$2:$E$185,G$3) -> 0 | H6: =COUNTIFS(Requirements!$B$2:$B$185,$A6,Requirements!$E$2:$E$185,H$3) -> 0 | I6: =SUM(E6:H6) -> 7 | J6: =COUNTIFS(Requirements!$B$2:$B$185,$A6,Requirements!$E$2:$E$185,"<>Met",Requirements!$K$2:$K$185,"Done")+COUNTIFS(Requirements!$B$2:$B$185,$A6,Requirements!$E$2:$E$185,"<>Met",Requirements!$K$2:$K$185,"Instructor accepted") -> 0 | K6: =MAX(0,I6-J6) -> 7 | L6: =IF(B6=0,0,(C6+D6)/B6) -> 0.61111111
A7: Cloud Security 1 | B7: =COUNTIF(Requirements!$B$2:$B$185,A7) -> 27 | C7: =COUNTIFS(Requirements!$B$2:$B$185,$A7,Requirements!$E$2:$E$185,C$3) -> 21 | D7: =COUNTIFS(Requirements!$B$2:$B$185,$A7,Requirements!$E$2:$E$185,D$3) -> 0 | E7: =COUNTIFS(Requirements!$B$2:$B$185,$A7,Requirements!$E$2:$E$185,E$3) -> 1 | F7: =COUNTIFS(Requirements!$B$2:$B$185,$A7,Requirements!$E$2:$E$185,F$3) -> 5 | G7: =COUNTIFS(Requirements!$B$2:$B$185,$A7,Requirements!$E$2:$E$185,G$3) -> 0 | H7: =COUNTIFS(Requirements!$B$2:$B$185,$A7,Requirements!$E$2:$E$185,H$3) -> 0 | I7: =SUM(E7:H7) -> 6 | J7: =COUNTIFS(Requirements!$B$2:$B$185,$A7,Requirements!$E$2:$E$185,"<>Met",Requirements!$K$2:$K$185,"Done")+COUNTIFS(Requirements!$B$2:$B$185,$A7,Requirements!$E$2:$E$185,"<>Met",Requirements!$K$2:$K$185,"Instructor accepted") -> 0 | K7: =MAX(0,I7-J7) -> 6 | L7: =IF(B7=0,0,(C7+D7)/B7) -> 0.77777778
A8: Risk Management 1 | B8: =COUNTIF(Requirements!$B$2:$B$185,A8) -> 25 | C8: =COUNTIFS(Requirements!$B$2:$B$185,$A8,Requirements!$E$2:$E$185,C$3) -> 24 | D8: =COUNTIFS(Requirements!$B$2:$B$185,$A8,Requirements!$E$2:$E$185,D$3) -> 0 | E8: =COUNTIFS(Requirements!$B$2:$B$185,$A8,Requirements!$E$2:$E$185,E$3) -> 1 | F8: =COUNTIFS(Requirements!$B$2:$B$185,$A8,Requirements!$E$2:$E$185,F$3) -> 0 | G8: =COUNTIFS(Requirements!$B$2:$B$185,$A8,Requirements!$E$2:$E$185,G$3) -> 0 | H8: =COUNTIFS(Requirements!$B$2:$B$185,$A8,Requirements!$E$2:$E$185,H$3) -> 0 | I8: =SUM(E8:H8) -> 1 | J8: =COUNTIFS(Requirements!$B$2:$B$185,$A8,Requirements!$E$2:$E$185,"<>Met",Requirements!$K$2:$K$185,"Done")+COUNTIFS(Requirements!$B$2:$B$185,$A8,Requirements!$E$2:$E$185,"<>Met",Requirements!$K$2:$K$185,"Instructor accepted") -> 0 | K8: =MAX(0,I8-J8) -> 1 | L8: =IF(B8=0,0,(C8+D8)/B8) -> 0.96
A9: Compliance 1 | B9: =COUNTIF(Requirements!$B$2:$B$185,A9) -> 21 | C9: =COUNTIFS(Requirements!$B$2:$B$185,$A9,Requirements!$E$2:$E$185,C$3) -> 21 | D9: =COUNTIFS(Requirements!$B$2:$B$185,$A9,Requirements!$E$2:$E$185,D$3) -> 0 | E9: =COUNTIFS(Requirements!$B$2:$B$185,$A9,Requirements!$E$2:$E$185,E$3) -> 0 | F9: =COUNTIFS(Requirements!$B$2:$B$185,$A9,Requirements!$E$2:$E$185,F$3) -> 0 | G9: =COUNTIFS(Requirements!$B$2:$B$185,$A9,Requirements!$E$2:$E$185,G$3) -> 0 | H9: =COUNTIFS(Requirements!$B$2:$B$185,$A9,Requirements!$E$2:$E$185,H$3) -> 0 | I9: =SUM(E9:H9) -> 0 | J9: =COUNTIFS(Requirements!$B$2:$B$185,$A9,Requirements!$E$2:$E$185,"<>Met",Requirements!$K$2:$K$185,"Done")+COUNTIFS(Requirements!$B$2:$B$185,$A9,Requirements!$E$2:$E$185,"<>Met",Requirements!$K$2:$K$185,"Instructor accepted") -> 0 | K9: =MAX(0,I9-J9) -> 0 | L9: =IF(B9=0,0,(C9+D9)/B9) -> 1
A10: Incident Response 1 | B10: =COUNTIF(Requirements!$B$2:$B$185,A10) -> 29 | C10: =COUNTIFS(Requirements!$B$2:$B$185,$A10,Requirements!$E$2:$E$185,C$3) -> 15 | D10: =COUNTIFS(Requirements!$B$2:$B$185,$A10,Requirements!$E$2:$E$185,D$3) -> 5 | E10: =COUNTIFS(Requirements!$B$2:$B$185,$A10,Requirements!$E$2:$E$185,E$3) -> 4 | F10: =COUNTIFS(Requirements!$B$2:$B$185,$A10,Requirements!$E$2:$E$185,F$3) -> 0 | G10: =COUNTIFS(Requirements!$B$2:$B$185,$A10,Requirements!$E$2:$E$185,G$3) -> 5 | H10: =COUNTIFS(Requirements!$B$2:$B$185,$A10,Requirements!$E$2:$E$185,H$3) -> 0 | I10: =SUM(E10:H10) -> 9 | J10: =COUNTIFS(Requirements!$B$2:$B$185,$A10,Requirements!$E$2:$E$185,"<>Met",Requirements!$K$2:$K$185,"Done")+COUNTIFS(Requirements!$B$2:$B$185,$A10,Requirements!$E$2:$E$185,"<>Met",Requirements!$K$2:$K$185,"Instructor accepted") -> 0 | K10: =MAX(0,I10-J10) -> 9 | L10: =IF(B10=0,0,(C10+D10)/B10) -> 0.68965517
A11: Capstone (Design Doc v1.2 + board) | B11: =COUNTIF(Requirements!$B$2:$B$185,A11) -> 37 | C11: =COUNTIFS(Requirements!$B$2:$B$185,$A11,Requirements!$E$2:$E$185,C$3) -> 10 | D11: =COUNTIFS(Requirements!$B$2:$B$185,$A11,Requirements!$E$2:$E$185,D$3) -> 0 | E11: =COUNTIFS(Requirements!$B$2:$B$185,$A11,Requirements!$E$2:$E$185,E$3) -> 10 | F11: =COUNTIFS(Requirements!$B$2:$B$185,$A11,Requirements!$E$2:$E$185,F$3) -> 17 | G11: =COUNTIFS(Requirements!$B$2:$B$185,$A11,Requirements!$E$2:$E$185,G$3) -> 0 | H11: =COUNTIFS(Requirements!$B$2:$B$185,$A11,Requirements!$E$2:$E$185,H$3) -> 0 | I11: =SUM(E11:H11) -> 27 | J11: =COUNTIFS(Requirements!$B$2:$B$185,$A11,Requirements!$E$2:$E$185,"<>Met",Requirements!$K$2:$K$185,"Done")+COUNTIFS(Requirements!$B$2:$B$185,$A11,Requirements!$E$2:$E$185,"<>Met",Requirements!$K$2:$K$185,"Instructor accepted") -> 0 | K11: =MAX(0,I11-J11) -> 27 | L11: =IF(B11=0,0,(C11+D11)/B11) -> 0.27027027
A12: TOTAL | B12: =SUM(B4:B11) -> 184 | C12: =SUM(C4:C11) -> 110 | D12: =SUM(D4:D11) -> 5 | E12: =SUM(E4:E11) -> 27 | F12: =SUM(F4:F11) -> 24 | G12: =SUM(G4:G11) -> 5 | H12: =SUM(H4:H11) -> 13 | I12: =SUM(I4:I11) -> 69 | ... K12: =SUM(K4:K11) -> 69 | L12: =IF(B12=0,0,(C12+D12)/B12) -> 0.625
A14: "Closed by you" counts rows not already Met where you set My status = Done or Instructor accepted.

Sheet Requirements
A1: ID | B1: Course | C1: Criterion | D1: Requirement (one checkable item) | E1: Status (verified 10/13) | F1: Evidence found (path) | G1: Gap / note | H1: Action to close | I1: Build task | J1: Capstone week | K1: My status | L1: Date closed | M1: New evidence file
A2: CB1-01 | B2: Cybersecurity Basics 1 | C2: 1 Incident Response Plan | D2: IR plan with >=1 method for detecting incidents | E2: Not found on computer | F2: Capstone equivalent: cloud_security_1/can-secops/IR-Playbook.md | G2: Course deliverable itself not found (only Desktop/Phishing_Awareness_AC demo) | H2: Confirm June grade on Schoology; nothing to rebuild if Complete | I2: B0 | J2: —
A3: CB1-02 | B3: Cybersecurity Basics 1 | C3: 1 Incident Response Plan | D3: >=1 containment strategy | E3: Not found on computer | F3: IR-Playbook.md §2 | H3: Same as above | I3: B0 | J3: —
A4: CB1-03 | B4: Cybersecurity Basics 1 | C4: 1 Incident Response Plan | D4: Eradication and recovery steps | E4: Not found on computer | F4: IR-Playbook.md; IR1 Section 6 | H4: Same as above | I4: B0 | J4: —
A5: CB1-04 | B5: Cybersecurity Basics 1 | C5: 1 Incident Response Plan | D5: Explain >=1 attack type (malware/phishing/ransomware/DoS) | E5: Partial | F5: Desktop/Phishing_Awareness_AC/cybersecurity_basics_1 (phishing awareness demo pptx + scripts) | G5: Phishing demo found; the plan document was not | H5: Confirm grade | I5: B0 | J5: —
A6: CB1-05 | B6: Cybersecurity Basics 1 | C6: 2 Security Policy | D6: Policy with >=3 security rules/guidelines | E6: Not found on computer | F6: Capstone equivalent: CAN-POL-AC-001 (Compliance 1 Task 2) | H6: Confirm grade | I6: B0 | J6: —
A7: CB1-06 | B7: Cybersecurity Basics 1 | C7: 2 Security Policy | D7: IR steps for a breach inside the policy | E7: Not found on computer | F7: Compliance 1 Task 5 incident scenario | H7: Confirm grade | I7: B0 | J7: —
A8: CB1-07 | B8: Cybersecurity Basics 1 | C8: 2 Security Policy | D8: How policies maintain the CIA triad | E8: Not found on computer | F8: — | H8: Add a CIA-triad paragraph to the capstone policy summary (5 min) | I8: B11 | J8: —
A9: CB1-08 | B9: Cybersecurity Basics 1 | C9: 3 Encryption | D9: AES-encrypted text + decrypted plaintext shown | E9: Not found on computer | F9: — | G9: Not in capstone evidence | H9: openssl AES-256 encrypt/decrypt of a synthetic ePHI export (data-at-rest demo for HIPAA §164.312(a)(2)(iv)) | I9: B11 | J9: —
A10: CB1-09 | B10: Cybersecurity Basics 1 | C10: 3 Encryption | D10: Text hashed with SHA/MD5 | E10: Met | F10: compliance_1/audit-evidence/EVIDENCE-INDEX-SHA256.txt; IR1 sha256 manifests | H10: — | J10: —
A11: CB1-10 | B11: Cybersecurity Basics 1 | C11: 4 Legal & Ethical | D11: >=2 relevant laws/regulations | E11: Met | F11: Compliance 1 Tasks 1 & 5 (HIPAA, PCI DSS, HITECH) | G11: Capstone equivalent | H11: — | J11: —
A12: CB1-11 | B12: Cybersecurity Basics 1 | C12: 4 Legal & Ethical | D12: >=1 ethical consideration + how plan upholds it | E12: Met | F12: Compliance 1 Task 5 ethical decision record | G12: Capstone equivalent | H12: — | J12: —
A13: CTV-01 | B13: Cyber Threats & Vulnerabilities 1 | C13: 1 Analyze Cyber Threats | D13: Malware sample analyzed in VirusTotal/Any.Run/Hybrid Analysis | E13: Met | F13: cyber_threats_and_vulnerabilities_1/CAN_Cyber_threats_and_vulnerabilities.pdf (AgentTesla, 34/70) | H13: — | J13: Wk 1-2
A14: CTV-02 | B14: Cyber Threats & Vulnerabilities 1 | C14: 1 Analyze Cyber Threats | D14: Detection results, behavioral indicators, potential impact documented | E14: Met | F14: Same PDF; Downloads/HRMC_Simulated_Malware_Incident_Report*.pdf | H14: — | J14: Wk 2
A15: CTV-03 | B15: Cyber Threats & Vulnerabilities 1 | C15: 1 Analyze Cyber Threats | D15: 1 phishing template built with SET in Kali/Parrot | E15: Met | F15: CAN_Cyber_threats_and_vulnerabilities.pdf (SET credential harvester) | H15: — | J15: Wk 2
A16: CTV-04 | B16: Cyber Threats & Vulnerabilities 1 | C16: 1 Analyze Cyber Threats | D16: 1 real APT campaign mapped to MITRE ATT&CK | E16: Met | F16: Same PDF (SilverTerrier, Orangeworm) | H16: — | J16: Wk 2
A17: CTV-05 | B17: Cyber Threats & Vulnerabilities 1 | C17: 2 Vulnerability Assessment | D17: Nmap/OpenVAS vulnerability scan: configuration, findings summary, classification | E17: Not found on computer | F17: Not in the 3 submitted CTV PDFs. Downloads/Care_Access_Navigator_Cyber_Threats_Report_REVISED*.docx contains example output for a 10.10.x lab that was never built | G17: Do not submit the REVISED docx output as real evidence | H17: Check Schoology grade; if needed, run a real scan of systems you own (your Azure VM public IP, Keycloak on localhost) or scanme.nmap.org | I17: B9 | J17: Wk 6
A18: CTV-06 | B18: Cyber Threats & Vulnerabilities 1 | C18: 2 Vulnerability Assessment | D18: 1 asset discovery scan: systems/services, critical assets, network map | E18: Not found on computer | F18: Same as above | H18: nmap -sn / -sV against your Docker network + Azure VNet; draw the map | I18: B9 | J18: Wk 6
A19: CTV-07 | B19: Cyber Threats & Vulnerabilities 1 | C19: 2 Vulnerability Assessment | D19: Methodology and security implications explained | E19: Not found on computer | F19: — | H19: Write-up with the real scan | I19: B9 | J19: Wk 6
A20: CTV-08 | B20: Cyber Threats & Vulnerabilities 1 | C20: 3 Threat Intelligence | D20: 2 IoCs analyzed with detection methods | E20: Met | F20: CAN_Cyber_Threat_Vulnerabilities_Assignment_task3.pdf | H20: — | J20: Wk 2
A21: CTV-09 | B21: Cyber Threats & Vulnerabilities 1 | C21: 3 Threat Intelligence | D21: OpenCTI deployed (Docker or system install) | E21: Partial | F21: task3 PDF: "instructor-confirmed: documentation satisfies this stage; live Docker deployment planned" | G21: Not deployed | H21: Ask instructor if doc-only is final; if not, deploy OpenCTI docker on your Mac (needs ~8 GB RAM) | I21: B9 | J21: —
A22: CTV-10 | B22: Cyber Threats & Vulnerabilities 1 | C22: 3 Threat Intelligence | D22: >=2 connectors configured | E22: Partial | F22: task3 PDF: MITRE ATT&CK + AlienVault OTX "proposed" | H22: Same as above | I22: B9 | J22: —
A23: CTV-11 | B23: Cyber Threats & Vulnerabilities 1 | C23: 3 Threat Intelligence | D23: Platform setup + connector integration documented, usage demo | E23: Partial | F23: Plan only | H23: Same as above | I23: B9 | J23: —
A24: CTV-12 | B24: Cyber Threats & Vulnerabilities 1 | C24: 4 Risk Strategies | D24: 2 critical risks identified FROM vulnerability scan results | E24: Not found on computer | F24: Not in submitted PDFs (Risk Mgmt R01-R05 exist but not scan-derived) | H24: Derive 2 risks from the real B9 scan; add to risk register | I24: B9 | J24: Wk 8
A25: CTV-13 | B25: Cyber Threats & Vulnerabilities 1 | C25: 4 Risk Strategies | D25: Treatment recommendations + mitigation steps | E25: Not found on computer | F25: — | H25: Same | I25: B9 | J25: Wk 8
A26: CTV-14 | B26: Cyber Threats & Vulnerabilities 1 | C26: 4 Risk Strategies | D26: 1 risk monitoring procedure | E26: Not found on computer | F26: Only in REVISED docx (unverified) | G26: Capstone KPI monitor + CAN-ID rules can serve | H26: Point to Compliance tracker KPI + detect rules | I26: B9 | J26: Wk 8
A27: CTV-15 | B27: Cyber Threats & Vulnerabilities 1 | C27: 5 Monitoring & IR | D27: 1 monitoring use case: detection rules, alert prioritization, response | E27: Partial | F27: Not in CTV PDFs; real equivalents now: Azure alerts (CS C6), CAN-ID-001..005 | H27: Reference CAN-ID-001 brute-force use case | I27: B6 | J27: Wk 6
A28: CTV-16 | B28: Cyber Threats & Vulnerabilities 1 | C28: 5 Monitoring & IR | D28: 1 IR scenario: classification, response steps, lessons learned | E28: Partial | F28: Downloads/HRMC_Simulated_Malware_Incident_Report_FILLED.docx (status SIMULATED/DRAFT, placeholders) | G28: Has "<fill from your test timeline>" placeholders | H28: Check grade; reuse INC-20261020-01 report if needed | I28: B6 | J28: Wk 7
A29: NS-01 | B29: Network Security 1 | C29: 1 Topologies | D29: Topology diagram for 1 configuration (LAN) | E29: Met | F29: network_security_1/CAN_Network_Security_tasks_1_to_5.pdf Fig 1 | G29: Labelled "design complete" | H29: — | J29: Wk 2
A30: NS-02 | B30: Network Security 1 | C30: 1 Topologies | D30: How topology supports secure communication and management | E30: Met | F30: Same | H30: — | J30: Wk 2
A31: NS-03 | B31: Network Security 1 | C31: 2 Protocols & Architecture | D31: Diagram with OSI + TCP/IP model for 1 device | E31: Met | F31: Same PDF | H31: — | J31: Wk 2
A32: NS-04 | B32: Network Security 1 | C32: 2 Protocols & Architecture | D32: Subnetting for 1 subnet | E32: Met | F32: Same PDF (/27, /24 plan) | H32: — | J32: Wk 2
A33: NS-05 | B33: Network Security 1 | C33: 2 Protocols & Architecture | D33: Secure architecture with specific security protocols | E33: Met | F33: Same PDF (TLS, OIDC/SAML over TLS) | H33: — | J33: Wk 2
A34: NS-06 | B34: Network Security 1 | C34: 3 Security Fundamentals | D34: 1 firewall rule IMPLEMENTED | E34: Partial | F34: NS report says "Not started; rule logic drafted". Real evidence exists: NSG rules (cloud_security_1 screenshots), policy deny re-test, IR1 iptables chain | G34: Submitted as plan, rubric says implementation | H34: Backfill: one page pointing to the real NSG/iptables rules | I34: B8 | J34: Wk 5-6
A35: NS-07 | B35: Network Security 1 | C35: 3 Security Fundamentals | D35: 1 IDS configuration | E35: Partial | F35: Drafted Suricata rule; real: Defender for Servers P2, sqr-ssh-bruteforce query (CS C6) | H35: Backfill with Defender/alert-rule config | I35: B8 | J35: Wk 6
A36: NS-08 | B36: Network Security 1 | C36: 3 Security Fundamentals | D36: 1 IPS configuration | E36: Partial | F36: Real: fail2ban ban (INC-20261008-01), iptables recent rate-limit (IR1 §6), Keycloak lockout (after B1) | H36: Backfill | I36: B8 | J36: Wk 6
A37: NS-09 | B37: Network Security 1 | C37: 3 Security Fundamentals | D37: 1 example of detected events | E37: Met | F37: cloud_security_1/can-secops/evidence/02-alerts-fired.txt, 10-bruteforce-alert-fired.txt | G37: Exists in another course pack | H37: Cross-reference in backfill | I37: B8 | J37: Wk 6
A38: NS-10 | B38: Network Security 1 | C38: 4 Access Control | D38: >=1 ACL configuration | E38: Partial | F38: Real NSG rules app-sg/data-sg/public-sg (screenshots in cloud_security_1) | G38: NS report: "not started" | H38: Backfill + app-gate output | I38: B8 | J38: Wk 3
A39: NS-11 | B39: Network Security 1 | C39: 4 Access Control | D39: 1 access control model (MAC/DAC/RBAC) | E39: Met | F39: NS report §4 (RBAC); RBAC matrix (Downloads/Care_Access_Navigator_RBAC_Matrix.docx) | H39: Attach app-gate allow/deny matrix | I39: B2 | J39: Wk 3
A40: NS-12 | B40: Network Security 1 | C40: 4 Access Control | D40: 1 user access level | E40: Partial | F40: RBAC matrix draft | G40: Not yet enforced | H40: B2 results | I40: B2 | J40: Wk 3
...

Sheet October Plan
A1: October build plan: each task closes capstone work AND course rubric items at the same time
A3: Task | B3: When | C3: Build task | D3: What you produce | E3: Requirement IDs it closes | F3: Open items closed (live) | G3: Courses served
A4: B0 | B4: Wed 10/14 | C4: Housekeeping & instructor confirmations | D4: Save IR 1 Sections 1-6 into incidence response_1/; one message to instructors (IR 1 tool substitution, NetSec 3-5 status, CTV OpenCTI); Monday board updates | E4: CB1-01, CB1-02, CB1-03, CB1-04, CB1-05, CB1-06, NS-14, IR-01, IR-02, IR-07, IR-08, IR-13, IR-15, IR-16, IR-17, IR-18, IR-19, IR-20, IR-21, IR-23, IR-24, IR-25, IR-26, IR-27, IR-28, IR-29, CAP-36 | F4: =COUNTIFS(Requirements!$I$2:$I$185,A4,Requirements!$E$2:$E$185,"<>Met") -> 17 | G4: Capstone; Cybersecurity Basics 1; Incident Response 1; Network Security 1
A5: B1 | B5: Wed 10/14 | C5: Keycloak hardening + RBAC groups | D5: can_iam.py harden --migrate: MFA for privileged roles, lockout, 12-char policy, 7 HRMC-* groups (before/after evidence) | E5: CAP-11 | F5: =COUNTIFS(Requirements!$I$2:$I$185,A5,Requirements!$E$2:$E$185,"<>Met") -> 1 | G5: Capstone
A6: B2 | B6: Wed 10/14 | C6: Application access gate + RBAC test matrix | D6: can_iam.py app-gate + verify: allow/deny matrix per role per app | E6: NS-11, NS-12, CAP-06, CAP-07 | F6: =COUNTIFS(Requirements!$I$2:$I$185,A6,Requirements!$E$2:$E$185,"<>Met") -> 3 | G6: Capstone; Network Security 1
A7: B3 | B7: Thu 10/15 | C7: Entra ID + Azure IAM build-out | D7: 7 Entra users, 7 security groups, Security defaults MFA, Azure custom role (JSON), ABAC condition on storage tags, least-privilege role assignments | E7: CS-13, CS-14, CS-15, CS-16, CAP-12 | F7: =COUNTIFS(Requirements!$I$2:$I$185,A7,Requirements!$E$2:$E$185,"<>Met") -> 5 | G7: Capstone; Cloud Security 1
A8: B4 | B8: Fri 10/16 | C8: SAML federation (Entra ID -> Keycloak) | D8: Entra enterprise app (SAML) as 2nd IdP in Keycloak; login test; SAML-tracer/assertion evidence | E8: CS-17, CS-18, CAP-16 | F8: =COUNTIFS(Requirements!$I$2:$I$185,A8,Requirements!$E$2:$E$185,"<>Met") -> 3 | G8: Capstone; Cloud Security 1
A9: B5 | B9: Mon 10/19 | C9: Access request + Joiner/Mover/Leaver | D9: Monday access-request form; can_iam.py joiner/mover/leaver (local + federated leaver) | E9: CAP-04, CAP-08, CAP-09, CAP-13, CAP-17 | F9: =COUNTIFS(Requirements!$I$2:$I$185,A9,Requirements!$E$2:$E$185,"<>Met") -> 5 | G9: Capstone
A10: B6 | B10: Tue 10/20 | C10: Identity attack simulation INC-20261020-01 | D10: Password spray, unapproved app, leaver reuse, privilege escalation; can_iam.py detect; containment; IR report; RCA | E10: CTV-15, CTV-16, RM-25, IR-22, CAP-14, CAP-18, CAP-21, CAP-22 | F10: =COUNTIFS(Requirements!$I$2:$I$185,A10,Requirements!$E$2:$E$185,"<>Met") -> 6 | G10: Capstone; Cyber Threats & Vulnerabilities 1; Incident Response 1; Risk Management 1
A11: B7 | B11: Wed 10/21 | C11: Access review + compliance re-test | D11: can_iam.py review + sign-off; re-run audit tests (F-01..F-06); compliance status report v2; compliance incident record | E11: CMP-13, CMP-21, CAP-10, CAP-23, CAP-28, CAP-30 | F11: =COUNTIFS(Requirements!$I$2:$I$185,A11,Requirements!$E$2:$E$185,"<>Met") -> 2 | G11: Capstone; Compliance 1
A12: B8 | B12: Thu 10/22 | C12: Network Security backfill pack | D12: Turn real evidence (NSG rules, Defender, fail2ban/iptables, app gate) into the "implemented" NS 3-5 evidence; Wi-Fi WPA2/3 evidence | E12: NS-06, NS-07, NS-08, NS-09, NS-10, NS-13, NS-14 | F12: =COUNTIFS(Requirements!$I$2:$I$185,A12,Requirements!$E$2:$E$185,"<>Met") -> 5 | G12: Network Security 1
A13: B9 | B13: Fri 10/23 | C13: Cyber Threats backfill | D13: Real Nmap vuln + discovery scan of systems you own; 2 critical risks from results; OpenCTI decision (deploy or confirmed doc-only) | E13: CTV-05, CTV-06, CTV-07, CTV-09, CTV-10, CTV-11, CTV-12, CTV-13, CTV-14 | F13: =COUNTIFS(Requirements!$I$2:$I$185,A13,Requirements!$E$2:$E$185,"<>Met") -> 9 | G13: Cyber Threats & Vulnerabilities 1
A14: B10 | B14: Mon-Tue 10/26-27 | C14: Tableau GRC + risk dashboard | D14: Dashboard with drill-down + threshold flags from tableau_dataset (serves Capstone Wk 11, RM C5, Compliance KPI) | E14: RM-24, CMP-15, CMP-17, CAP-32 | F14: =COUNTIFS(Requirements!$I$2:$I$185,A14,Requirements!$E$2:$E$185,"<>Met") -> 2 | G14: Capstone; Compliance 1; Risk Management 1
A15: B11 | B15: Wed 10/28 | C15: Audit pack + evidence repository + GitHub | D15: SoA, POA&M, exception register, AES-256 encryption demo, realm export; push compliance_1/IR1/capstone to GitHub (no secrets) | E15: CB1-07, CB1-08, CAP-20, CAP-24, CAP-27, CAP-29, CAP-31, CAP-33 | F15: =COUNTIFS(Requirements!$I$2:$I$185,A15,Requirements!$E$2:$E$185,"<>Met") -> 8 | G15: Capstone; Cybersecurity Basics 1
A16: B12 | B16: Thu-Fri 10/29-30 | C16: End-to-end test + portfolio + demo | D16: Re-run verify/detect/review; expected-vs-actual test log; 5-minute demo rehearsal; close-out | E16: CAP-34, CAP-35, CAP-37 | F16: =COUNTIFS(Requirements!$I$2:$I$185,A16,Requirements!$E$2:$E$185,"<>Met") -> 3 | G16: Capstone
A18: Column F counts rows whose Build task is exactly this task (combined values such as "B0/B8" are listed in column E but not counted).
